// qnd for erro do dev, retornar excecao
const { MissingParamError } = require('../../utils/generic-errors')
class AuthUseCase {
  constructor (loadUserByEmailRepository) {
    this.loadUserByEmailRepository = loadUserByEmailRepository
  }

  async auth (email, password) {
    if (!email) {
      throw new MissingParamError('email')
    }
    if (!password) {
      throw new MissingParamError('password')
    }

    await this.loadUserByEmailRepository.load(email)
  }
}

describe('Auth UseCase', () => {
  test('Should return null if no email is provider', async () => {
    // jest não funfa pra testar exceção com assíncrono
    const sut = new AuthUseCase()
    const promise = sut.auth()
    expect(promise).rejects.toThrow(new MissingParamError('email'))
  })

  test('Should return null if no password is provider', async () => {
    // jest não funfa pra testar exceção com assíncrono
    const sut = new AuthUseCase()
    const promise = sut.auth('any_email@email.com')
    expect(promise).rejects.toThrow(new MissingParamError('password'))
  })

  test('Should call LoadUserByEmailRepository with correct email', async () => {
    class LoadUserByEmailRepositorySpy {
      async load (email) {
        this.email = email
      }
    }
    const loadUserByEmailRepositorySpy = new LoadUserByEmailRepositorySpy()
    const sut = new AuthUseCase(loadUserByEmailRepositorySpy)

    await sut.auth('any_email@email.com', 'any_email@email.com')
    expect(loadUserByEmailRepositorySpy.email).toBe('any_email@email.com')
  })
})
